<mujoco model="spot_legs">
<!-- Copyright (c) 2025 Boston Dynamics AI Institute LLC. All rights reserved. -->
    <body name="front_left_hip" pos="0.29785 0.055 0">
        <inertial pos="-0.01586739 0.00855842 0.00000903" mass="1.13688339" fullinertia="0.00122166 0.00158957 0.00172903 -0.00017754 0.00000043 -0.00000049"/>
        <joint name="fl_hx" class="hip_x" pos="0 0 0" axis="1 0 0" range="-0.785398 0.785398"/>
        <geom name="front_left_hip_visual" class="visual" mesh="front_left_hip_visual" material="black"/>
        <body name="front_left_upper_leg" pos="0 0.110945 0">
            <inertial pos="0.00214442 -0.01110184 -0.07881204" mass="2.25620359" fullinertia="0.02692501 0.02583907 0.00318737 -0.00008782 0.00054873 0.00207146"/>
            <joint name="fl_hy" class="hip_y" pos="0 0 0" axis="0 1 0" range="-0.898845 2.295108"/>
            <geom name="front_left_upper_leg_0_visual" class="visual" mesh="front_left_upper_leg_0_visual" material="yellow"/>
            <geom name="front_left_upper_leg_1_visual" class="visual" mesh="front_left_upper_leg_1_visual" material="black"/>
            <geom name="front_left_upper_leg_collision" type="mesh" class="collision" mesh="left_upper_leg_collision"/>
            <body name="front_left_lower_leg" pos="0.025 0 -0.3205">
                <inertial pos="0.00597360 0.0 -0.17466427" mass="0.33" fullinertia="0.00701356 0.00709946 0.00014529 0 0.00006600 0"/>
                <joint name="fl_kn" class="knee" pos="0 0 0" axis="0 1 0" range="-2.7929 -0.2471"/>
                <geom name="front_left_lower_leg_visual" class="visual" mesh="front_left_lower_leg_visual" material="black"/>
                <geom name="front_left_lower_leg_collision" type="mesh" class="collision" mesh="left_lower_leg_collision"/>
                <geom name="front_left_foot_collision" class="collision" type="sphere" size="0.036" pos="0 0 -0.3365"/>
                <site name="site_front_left" pos="0 0 -0.3365" size="0.01"/>
            </body>
        </body>
    </body>

    <body name="front_right_hip" pos="0.29785 -0.055 0">
        <inertial pos="-0.01586739 -0.00855842 0.00000903" mass="1.13688339" fullinertia="0.00122166 0.00158957 0.00172903 0.00017754 0.00000043 0.00000049"/>
        <joint name="fr_hx" class="hip_x" pos="0 0 0" axis="1 0 0" range="-0.785398 0.785398"/>
        <geom name="front_right_hip_visual" class="visual" mesh="front_right_hip_visual" material="black"/>
        <body name="front_right_upper_leg" pos="0 -0.110945 0">
            <inertial pos="0.00214442 0.01110184 -0.07881204" mass="2.25620359" fullinertia="0.02692501 0.02583907 0.00318737 0.00008782 0.00054873 -0.00207146"/>
            <joint name="fr_hy" class="hip_y" pos="0 0 0" axis="0 1 0" range="-0.898845 2.295108"/>
            <geom name="front_right_upper_leg_0_visual" class="visual" mesh="front_right_upper_leg_0_visual" material="yellow"/>
            <geom name="front_right_upper_leg_1_visual" class="visual" mesh="front_right_upper_leg_1_visual" material="black"/>
            <geom name="front_right_upper_leg_collision" type="mesh" class="collision" mesh="right_upper_leg_collision"/>
            <body name="front_right_lower_leg" pos="0.025 0 -0.3205">
                <inertial pos="0.00597360 0.0 -0.17466427" mass="0.33" fullinertia="0.00701356 0.00709946 0.00014529 0 0.00006600 0"/>
                <joint name="fr_kn" class="knee" pos="0 0 0" axis="0 1 0" range="-2.7929 -0.2471"/>
                <geom name="front_right_lower_leg_visual" class="visual" mesh="front_right_lower_leg_visual" material="black"/>
                <geom name="front_right_lower_leg_collision" type="mesh" class="collision" mesh="right_lower_leg_collision"/>
                <geom name="front_right_foot_collision" class="collision" type="sphere" size="0.036" pos="0 0 -0.3365"/>
                <site name="site_front_right" pos="0 0 -0.3365" size="0.01"/>
            </body>
        </body>
    </body>

    <body name="rear_left_hip" pos="-0.29785 0.055 0">
        <inertial pos="0.01586739 0.00855842 0.00000903" mass="1.13688339" fullinertia="0.00122166 0.00158957 0.00172903 0.00017754 -0.00000043 -0.00000049"/>
        <joint name="hl_hx" class="hip_x" pos="0 0 0" axis="1 0 0" range="-0.785398 0.785398"/>
        <geom name="rear_left_hip_visual" class="visual" mesh="rear_left_hip_visual" material="black"/>
        <body name="rear_left_upper_leg" pos="0 0.110945 0">
            <inertial pos="0.00214442 -0.01110184 -0.07881204" mass="2.25620359" fullinertia="0.02692501 0.02583907 0.00318737 -0.00008782 0.00054873 0.00207146"/>
            <joint name="hl_hy" class="hip_y" pos="0 0 0" axis="0 1 0" range="-0.898845 2.295108"/>
            <geom name="rear_left_upper_leg_0_visual" class="visual" mesh="rear_left_upper_leg_0_visual" material="yellow"/>
            <geom name="rear_left_upper_leg_1_visual" class="visual" mesh="rear_left_upper_leg_1_visual" material="black"/>
            <geom name="rear_left_upper_leg_collision" type="mesh" class="collision" mesh="left_upper_leg_collision"/>
            <body name="rear_left_lower_leg" pos="0.025 0 -0.3205">
                <inertial pos="0.00597360 0.0 -0.17466427" mass="0.33" fullinertia="0.00701356 0.00709946 0.00014529 0 0.00006600 0"/>
                <joint name="hl_kn" class="knee" pos="0 0 0" axis="0 1 0" range="-2.7929 -0.2471"/>
                <geom name="rear_left_lower_leg_visual" class="visual" mesh="rear_left_lower_leg_visual" material="black"/>
                <geom name="rear_left_lower_leg_collision" type="mesh" class="collision" mesh="left_lower_leg_collision"/>
                <geom name="rear_left_foot_collision" class="collision" type="sphere" size="0.036" pos="0 0 -0.3365"/>
                <site name="site_rear_left" pos="0 0 -0.3365" size="0.01"/>
            </body>
        </body>
    </body>

    <body name="rear_right_hip" pos="-0.29785 -0.055 0">
        <inertial pos="0.01586739 -0.00855842 0.00000903" mass="1.13688339" fullinertia="0.00122166 0.00158957 0.00172903 -0.00017754 -0.00000043 0.00000049"/>
        <joint name="hr_hx" class="hip_x" pos="0 0 0" axis="1 0 0" range="-0.785398 0.785398"/>
        <geom name="rear_right_hip_visual" class="visual" mesh="rear_right_hip_visual" material="black"/>
        <body name="rear_right_upper_leg" pos="0 -0.110945 0">
            <inertial pos="0.00214442 0.01110184 -0.07881204" mass="2.25620359" fullinertia="0.02692501 0.02583907 0.00318737 0.00008782 0.00054873 -0.00207146"/>
            <joint name="hr_hy" class="hip_y" pos="0 0 0" axis="0 1 0" range="-0.898845 2.295108"/>
            <geom name="rear_right_upper_leg_0_visual" class="visual" mesh="rear_right_upper_leg_0_visual" material="yellow"/>
            <geom name="rear_right_upper_leg_1_visual" class="visual" mesh="rear_right_upper_leg_1_visual" material="black"/>
            <geom name="rear_right_upper_leg_collision" type="mesh" class="collision" mesh="right_upper_leg_collision"/>
            <body name="rear_right_lower_leg" pos="0.025 0 -0.3205">
                <inertial pos="0.00597360 0.0 -0.17466427" mass="0.33" fullinertia="0.00701356 0.00709946 0.00014529 0 0.00006600 0"/>
                <joint name="hr_kn" class="knee" pos="0 0 0" axis="0 1 0" range="-2.7929 -0.2471"/>
                <geom name="rear_right_lower_leg_visual" class="visual" mesh="rear_right_lower_leg_visual" material="black"/>
                <geom name="rear_right_lower_leg_collision" type="mesh" class="collision" mesh="right_lower_leg_collision"/>
                <geom name="rear_right_foot_collision" class="collision" type="sphere" size="0.036" pos="0 0 -0.3365"/>
                <site name="site_rear_right" pos="0 0 -0.3365" size="0.01"/>
            </body>
        </body>
    </body>
</mujoco>
